Workbook

Sheet Resumo
B2: Conta Comigo — Levantamento de 750 Melhorias
B4: Metodologia: levantamento original elaborado em outubro de 2026 para o aplicativo Conta Comigo (extensão
B5: Chromium + Firefox de matemática lúdica para crianças a partir de 4 anos). Cada item traz domínio, título,
B6: descrição, esforço estimado (Pequeno/Médio/Grande) e faixa de versão sugerida (v2.4-v2.5 curto prazo,
B7: v2.6-v2.9 médio prazo, v3.x longo prazo, Futuro = ideia a validar). Use os filtros das abas para cruzar
B8: domínio x esforço x faixa. Itens já entregues nas versões até 2.3.0 não foram repetidos de propósito.
B10: Impacto | C10: Itens | D10: Domínios | E10: Aba
B11: Alto | C11: =COUNTA('Alto impacto (250)'!B5:B254) -> 250 | D11: 9 | E11: Alto impacto (250)
B12: Médio | C12: =COUNTA('Médio impacto (250)'!B5:B254) -> 250 | D12: 8 | E12: Médio impacto (250)
B13: Baixo | C13: =COUNTA('Baixo impacto (250)'!B5:B254) -> 250 | D13: 6 | E13: Baixo impacto (250)
B14: Total | C14: =SUM(C11:C13) -> 750 | D14: 23
B16: Esforço × Impacto (contagem de itens)
B17: Esforço | C17: Alto | D17: Médio | E17: Baixo
B18: Pequeno | C18: =COUNTIF('Alto impacto (250)'!F5:F254,"Pequeno") -> 159 | D18: =COUNTIF('Médio impacto (250)'!F5:F254,"Pequeno") -> 174 | E18: =COUNTIF('Baixo impacto (250)'!F5:F254,"Pequeno") -> 193
B19: Médio | C19: =COUNTIF('Alto impacto (250)'!F5:F254,"Médio") -> 73 | D19: =COUNTIF('Médio impacto (250)'!F5:F254,"Médio") -> 68 | E19: =COUNTIF('Baixo impacto (250)'!F5:F254,"Médio") -> 48
B20: Grande | C20: =COUNTIF('Alto impacto (250)'!F5:F254,"Grande") -> 18 | D20: =COUNTIF('Médio impacto (250)'!F5:F254,"Grande") -> 8 | E20: =COUNTIF('Baixo impacto (250)'!F5:F254,"Grande") -> 9
B21: Total | C21: =SUM(C18:C20) -> 250 | D21: =SUM(D18:D20) -> 250 | E21: =SUM(E18:E20) -> 250
B23: Domínios por impacto
B24: Impacto | C24: Domínio | D24: Itens
B25: Alto | C25: Acessibilidade e Inclusão | D25: =COUNTIF('Alto impacto (250)'!C5:C254,"Acessibilidade e Inclusão") -> 30
B26: Alto | C26: Adaptatividade e IA | D26: =COUNTIF('Alto impacto (250)'!C5:C254,"Adaptatividade e IA") -> 30
B27: Alto | C27: Controle Parental e Família | D27: =COUNTIF('Alto impacto (250)'!C5:C254,"Controle Parental e Família") -> 25
B28: Alto | C28: Gamificação e Motivação | D28: =COUNTIF('Alto impacto (250)'!C5:C254,"Gamificação e Motivação") -> 30
B29: Alto | C29: Pedagogia e Currículo | D29: =COUNTIF('Alto impacto (250)'!C5:C254,"Pedagogia e Currículo") -> 35
B30: Alto | C30: Plataforma e Arquitetura | D30: =COUNTIF('Alto impacto (250)'!C5:C254,"Plataforma e Arquitetura") -> 25
B31: Alto | C31: Relatórios e Acompanhamento | D31: =COUNTIF('Alto impacto (250)'!C5:C254,"Relatórios e Acompanhamento") -> 25
B32: Alto | C32: Segurança e Privacidade | D32: =COUNTIF('Alto impacto (250)'!C5:C254,"Segurança e Privacidade") -> 25
B33: Alto | C33: Voz, Som e Narração | D33: =COUNTIF('Alto impacto (250)'!C5:C254,"Voz, Som e Narração") -> 25
B34: Médio | C34: Desempenho e Estabilidade | D34: =COUNTIF('Médio impacto (250)'!C5:C254,"Desempenho e Estabilidade") -> 25
B35: Médio | C35: Interface e Navegação | D35: =COUNTIF('Médio impacto (250)'!C5:C254,"Interface e Navegação") -> 40
B36: Médio | C36: Internacionalização | D36: =COUNTIF('Médio impacto (250)'!C5:C254,"Internacionalização") -> 35
B37: Médio | C37: Modos de Jogo e Conteúdo | D37: =COUNTIF('Médio impacto (250)'!C5:C254,"Modos de Jogo e Conteúdo") -> 40
B38: Médio | C38: Offline, Sincronização e Dados | D38: =COUNTIF('Médio impacto (250)'!C5:C254,"Offline, Sincronização e Dados") -> 25
B39: Médio | C39: Onboarding e Ajuda | D39: =COUNTIF('Médio impacto (250)'!C5:C254,"Onboarding e Ajuda") -> 25
B40: Médio | C40: Progressão, Recompensas e Loja | D40: =COUNTIF('Médio impacto (250)'!C5:C254,"Progressão, Recompensas e Loja") -> 35
B41: Médio | C41: Social Seguro | D41: =COUNTIF('Médio impacto (250)'!C5:C254,"Social Seguro") -> 25
B42: Baixo | C42: Configurações Avançadas | D42: =COUNTIF('Baixo impacto (250)'!C5:C254,"Configurações Avançadas") -> 35
B43: Baixo | C43: Diversão e Easter Eggs | D43: =COUNTIF('Baixo impacto (250)'!C5:C254,"Diversão e Easter Eggs") -> 35
B44: Baixo | C44: Ideias Criativas | D44: =COUNTIF('Baixo impacto (250)'!C5:C254,"Ideias Criativas") -> 60
B45: Baixo | C45: Polimento Visual | D45: =COUNTIF('Baixo impacto (250)'!C5:C254,"Polimento Visual") -> 45
...

Sheet Alto impacto (250)
B2: Melhorias de alto impacto — 250 itens
B4: ID | C4: Domínio | D4: Melhoria | E4: Descrição | F4: Esforço | G4: Faixa sugerida
B5: A-001 | C5: Pedagogia e Currículo | D5: Trilha curricular por idade | E5: Sequência de modos sugerida por faixa etária (4-5, 6-7, 8-10+), guiando a criança do reconhecimento de quantidades até a tabuada, com trilha visual clicável na tela inicial. | F5: Médio | G5: v2.6-v2.9
B6: A-002 | C6: Pedagogia e Currículo | D6: Números até 100 | E6: Novo bloco de conteúdo com dezenas e unidades visuais (barras de 10), ampliando a contagem além de 20 nos níveis altos. | F6: Grande | G6: v2.6-v2.9
B7: A-003 | C7: Pedagogia e Currículo | D7: Valor posicional | E7: Questões de dezenas e unidades (quantas dezenas há em 34) com visual de blocos base-10 para consolidar o sistema decimal. | F7: Médio | G7: v3.x
B8: A-004 | C8: Pedagogia e Currículo | D8: Tabela de números de 1 a 100 | E8: Quadro interativo de centena tocável na tela inicial, onde a criança explora padrões (pares, ímpares, dezenas) livremente. | F8: Pequeno | G8: v2.6-v2.9
B9: A-005 | C9: Pedagogia e Currículo | D9: Contar de 2 em 2, de 5 em 5 | E9: Modo de contagens saltitantes com trilha de sapinhos pulando, preparando multiplicação e frações. | F9: Pequeno | G9: v2.6-v2.9
B10: A-006 | C10: Pedagogia e Currículo | D10: Frações visuais iniciais | E10: Pizza e barras divididas em partes iguais: metade, terço, quarto com coloração interativa, como fundação para frações. | F10: Grande | G10: v3.x
B11: A-007 | C11: Pedagogia e Currículo | D11: Relógio e horas cheias | E11: Modo de reconhecer horas no relógio analógico tocável (mover ponteiros) e depois meias horas. | F11: Médio | G11: v2.6-v2.9
B12: A-008 | C12: Pedagogia e Currículo | D12: Medidas simples | E12: Comparar comprimentos e pesos com objetos ilustrados (mais alto, mais pesado), ampliando o modo Comparar. | F12: Médio | G12: v3.x
B13: A-009 | C13: Pedagogia e Currículo | D13: Formas geométricas | E13: Reconhecer círculo, quadrado, triângulo e retângulo em cenas do jogo, contando lados e achando formas escondidas. | F13: Médio | G13: v2.6-v2.9
B14: A-010 | C14: Pedagogia e Currículo | D14: Padrões com formas | E14: Sequências ABAB e AAB com formas e cores além dos números, expandindo o modo Sequência. | F14: Pequeno | G14: v2.6-v2.9
B15: A-011 | C15: Pedagogia e Currículo | D15: Contagem regressiva | E15: Questões de tirar um por um até zero com foguete de lançamento, reforçando a ideia de subtração como tirar. | F15: Pequeno | G15: v2.6-v2.9
... B254: A-250 | C254: Plataforma e Arquitetura | D254: Números mágicos centralizados | E254: Constantes de jogo (orçamentos, bônus) em config único documentado, facilitando balanceamento. | F254: Pequeno | G254: v2.4-v2.5

Sheet Médio impacto (250)
B2: Melhorias de médio impacto — 250 itens
B4: ID | C4: Domínio | D4: Melhoria | E4: Descrição | F4: Esforço | G4: Faixa sugerida
B5: M-001 | C5: Modos de Jogo e Conteúdo | D5: Modo peso e balança | E5: Comparar objetos em balanças de dois pratos (mais pesado, mais leve, igual), expandindo comparação para medidas. | F5: Médio | G5: v3.x
B6: M-002 | C6: Modos de Jogo e Conteúdo | D6: Modo trem de vagões | E6: Contar vagões, completar o trem faltante e juntar dois trens (soma com contexto ferroviário). | F6: Médio | G6: v3.x
B7: M-003 | C7: Modos de Jogo e Conteúdo | D7: Modo feira | E7: Comprar frutas em quantidade com preços redondos, ampliando dinheiro para multiplicações simples. | F7: Médio | G7: v3.x
B8: M-004 | C8: Modos de Jogo e Conteúdo | D8: Modo peixaria | E8: Dividir peixes igualmente entre tanques com animação de nado, contexto novo para divisão. | F8: Médio | G8: v3.x
B9: M-005 | C9: Modos de Jogo e Conteúdo | D9: Modo corrida até 20 | E9: Cada acerto avança casas num tabuleiro corrido contra a raposa, com fim comemorativo. | F9: Médio | G9: v2.6-v2.9
B10: M-006 | C10: Modos de Jogo e Conteúdo | D10: Quebra-cabeça numérico | E10: Encaixar peças de 1 a 10 no lugar certo do tabuleiro de madeira virtual. | F10: Médio | G10: v2.6-v2.9
B11: M-007 | C11: Modos de Jogo e Conteúdo | D11: Memória das continhas | E11: Jogo da memória casando conta com resultado (3+2 com 5), clássico que ancora fatos. | F11: Médio | G11: v2.6-v2.9
B12: M-008 | C12: Modos de Jogo e Conteúdo | D12: Dominó de pontos | E12: Dominó tradicional com pontinhos, casando quantidades iguais, para 1 ou 2 jogadores locais. | F12: Médio | G12: v3.x
B13: M-009 | C13: Modos de Jogo e Conteúdo | D13: Boliche da subtração | E13: Derrubar pinos e calcular quantos ficaram (10 - 4), subtração corporal e divertida. | F13: Médio | G13: v2.6-v2.9
B14: M-010 | C14: Modos de Jogo e Conteúdo | D14: Máquina de refrigerante | E14: Inserir moedas certas para comprar, treino de composição de valores com máquina tocável. | F14: Médio | G14: v3.x
B15: M-011 | C15: Modos de Jogo e Conteúdo | D15: Modo estacionamento | E15: Estacionar carinhos numerados na vaga certa (número, ou resultado da conta), ordenação e identificação. | F15: Médio | G15: v2.6-v2.9
... B254: M-250 | C254: Internacionalização | D254: Revisão profissional por idioma | E254: Contratar revisão nativa dos 3 idiomas atuais (qualidade editorial). | F254: Médio | G254: v2.6-v2.9

Sheet Baixo impacto (250)
B2: Melhorias de baixo impacto — 250 itens
B4: ID | C4: Domínio | D4: Melhoria | E4: Descrição | F4: Esforço | G4: Faixa sugerida
B5: B-001 | C5: Polimento Visual | D5: Squash and stretch na mascote | E5: A raposa comprime e estica levemente ao reagir (princípio clássico de animação). | F5: Pequeno | G5: v2.6-v2.9
B6: B-002 | C6: Polimento Visual | D6: Piscar de olhos da mascote | E6: A raposa pisca em intervalos aleatórios na home (vida sutil). | F6: Pequeno | G6: v2.4-v2.5
B7: B-003 | C7: Polimento Visual | D7: Cauda balançando | E7: Animação CSS da cauda da raposa em loop lento quando ociosa. | F7: Pequeno | G7: v2.6-v2.9
B8: B-004 | C8: Polimento Visual | D8: Confete dourado em recordes | E8: Recordes de pontos usam confete dourado exclusivo, distinção visual de momento raro. | F8: Pequeno | G8: v2.4-v2.5
B9: B-005 | C9: Polimento Visual | D9: Parallax leve na home | E9: Cenário de fundo move 4px com o mouse (desligável pelo modo calmo). | F9: Pequeno | G9: v2.6-v2.9
B10: B-006 | C10: Polimento Visual | D10: Balões de fala com cauda animada | E10: Bolinha do balão balança quando a fala chega. | F10: Pequeno | G10: v2.6-v2.9
B11: B-007 | C11: Polimento Visual | D11: Transição de estrelas voadoras | E11: Estrela do acerto voa em arco até o contador (caminho curvo, não reto). | F11: Pequeno | G11: v2.6-v2.9
B12: B-008 | C12: Polimento Visual | D12: Botão pressionado com sombra | E12: Sombra dura desce 2px no :active de todos os botões (já parcial) padronizar. | F12: Pequeno | G12: v2.4-v2.5
B13: B-009 | C13: Polimento Visual | D13: Lupa nas questões com muitos objetos | E13: Grupos grandes (15+) recebem zoom suave alternado por fileira. | F13: Pequeno | G13: v3.x
B14: B-010 | C14: Polimento Visual | D14: Fundo do jogo por modo | E14: Cada modo tem um gradiente de fundo próprio sutil (contar vermelho quente, dinheiro verde oliva). | F14: Pequeno | G14: v2.6-v2.9
B15: B-011 | C15: Polimento Visual | D15: Chuva de estrelas no combo 5 | E15: Combo de 5 dispara chuva de estrelas em vez de confete comum. | F15: Pequeno | G15: v2.4-v2.5
... B254: B-250 | C254: Ideias Criativas | D254: Lanchonete das trocas | E254: Montar lanche com dinheiro exato (síntese econômica). | F254: Médio | G254: v3.x
