Workbook

Sheet Resumo
B2: Conta Comigo — Levantamento de 150 Melhorias
B4: Metodologia: novo levantamento elaborado em outubro de 2026 para o aplicativo Conta Comigo (extensão
B5: Chromium + Firefox de matemática lúdica para crianças a partir de 4 anos), conforme solicitado: 50 itens de
B6: alto impacto, 50 de médio e 50 de baixo. Esta edição é COMPLEMENTAR e INÉDITA em relação ao levantamento
B7: anterior de 750 itens (arquivo Conta-Comigo-750-Melhorias.xlsx): nenhum título se repete entre as duas edições.
B8: Cada item traz domínio, título, descrição, esforço estimado (Pequeno/Médio/Grande) e faixa de versão sugerida
B9: (v2.4-v2.5 curto prazo, v2.6-v2.9 médio prazo, v3.x longo prazo). Use os filtros das abas para cruzar domínio,
B10: esforço e faixa. Nenhum item já entregue nas versões até 2.3.0 foi incluído.
B12: Impacto | C12: Itens | D12: Domínios | E12: Aba
B13: Alto | C13: =COUNTA('Alto impacto (50)'!B5:B54) -> 50 | D13: 8 | E13: Alto impacto (50)
B14: Médio | C14: =COUNTA('Médio impacto (50)'!B5:B54) -> 50 | D14: 13 | E14: Médio impacto (50)
B15: Baixo | C15: =COUNTA('Baixo impacto (50)'!B5:B54) -> 50 | D15: 12 | E15: Baixo impacto (50)
B16: Total | C16: =SUM(C13:C15) -> 150 | D16: 33
B18: Esforço × Impacto (contagem de itens)
B19: Esforço | C19: Alto | D19: Médio | E19: Baixo
B20: Pequeno | C20: =COUNTIF('Alto impacto (50)'!F5:F54,"Pequeno") -> 11 | D20: =COUNTIF('Médio impacto (50)'!F5:F54,"Pequeno") -> 29 | E20: =COUNTIF('Baixo impacto (50)'!F5:F54,"Pequeno") -> 50
B21: Médio | C21: =COUNTIF('Alto impacto (50)'!F5:F54,"Médio") -> 34 | D21: =COUNTIF('Médio impacto (50)'!F5:F54,"Médio") -> 21 | E21: =COUNTIF('Baixo impacto (50)'!F5:F54,"Médio") -> 0
B22: Grande | C22: =COUNTIF('Alto impacto (50)'!F5:F54,"Grande") -> 5 | D22: =COUNTIF('Médio impacto (50)'!F5:F54,"Grande") -> 0 | E22: =COUNTIF('Baixo impacto (50)'!F5:F54,"Grande") -> 0
B23: Total | C23: =SUM(C20:C22) -> 50 | D23: =SUM(D20:D22) -> 50 | E23: =SUM(E20:E22) -> 50
B25: Destaques de alto impacto (10 primeiros da aba)
B26: ID | C26: Melhoria | D26: Esforço
B27: A-150-001 | C27: Distribuição um a um | D27: Médio
B28: A-150-002 | C28: Antes, depois e entre | D28: Pequeno
B29: A-150-003 | C29: Conservação de quantidade | D29: Médio
B30: A-150-004 | C30: Qual é o sinal? | D30: Pequeno
B31: A-150-005 | C31: Verdadeiro ou falso matemático | D31: Pequeno
B32: A-150-006 | C32: Somar três parcelas | D32: Médio
B33: A-150-007 | C33: Famílias de fatos | D33: Médio
B34: A-150-008 | C34: Arredondamento na feira | D34: Médio
B35: A-150-009 | C35: Ordinais na corrida | D35: Pequeno
B36: A-150-010 | C36: Calendário da criança | D36: Médio
B38: Domínios por impacto
B39: Impacto | C39: Domínio | D39: Itens
B40: Alto | C40: Acessibilidade e Inclusão | D40: =COUNTIF('Alto impacto (50)'!C5:C54,"Acessibilidade e Inclusão") -> 5
B41: Alto | C41: Controle Parental e Família | D41: =COUNTIF('Alto impacto (50)'!C5:C54,"Controle Parental e Família") -> 2
B42: Alto | C42: Gamificação e Motivação | D42: =COUNTIF('Alto impacto (50)'!C5:C54,"Gamificação e Motivação") -> 3
B43: Alto | C43: Modos de Jogo e Conteúdo | D43: =COUNTIF('Alto impacto (50)'!C5:C54,"Modos de Jogo e Conteúdo") -> 14
B44: Alto | C44: Pedagogia e Currículo | D44: =COUNTIF('Alto impacto (50)'!C5:C54,"Pedagogia e Currículo") -> 22
B45: Alto | C45: Plataforma e Arquitetura | D45: =COUNTIF('Alto impacto (50)'!C5:C54,"Plataforma e Arquitetura") -> 1
B46: Alto | C46: Social Seguro | D46: =COUNTIF('Alto impacto (50)'!C5:C54,"Social Seguro") -> 1
...

Sheet Alto impacto (50)
B2: Melhorias de alto impacto — 50 itens inéditos
B4: ID | C4: Domínio | D4: Melhoria | E4: Descrição | F4: Esforço | G4: Faixa sugerida
B5: A-150-001 | C5: Pedagogia e Currículo | D5: Distribuição um a um | E5: Dar exatamente um biscoito para cada urso arrastando itens, consolidando a correspondência um-para-um que sustenta toda a contagem e a comparação de coleções nos 4 anos. | F5: Médio | G5: v2.4-v2.5
B6: A-150-002 | C6: Pedagogia e Currículo | D6: Antes, depois e entre | E6: Questões de números vizinhos (qual vem antes de 8, qual fica entre 12 e 14) com trilha visual de pedrinhas, fechando a compreensão da reta numérica nos pequenos. | F6: Pequeno | G6: v2.4-v2.5
B7: A-150-003 | C7: Pedagogia e Currículo | D7: Conservação de quantidade | E7: Desafios ao estilo Piaget: o mesmo número apresentado em arranjos diferentes (apertado ou espalhado) e a criança responde se ainda é igual, reforçando o raciocínio conservacional. | F7: Médio | G7: v2.6-v2.9
B8: A-150-004 | C8: Pedagogia e Currículo | D8: Qual é o sinal? | E8: Questões com a operação faltante (4 ? 2 = 6) em que a criança escolhe entre mais, menos e igual, aprendendo a ler a estrutura da conta e não apenas o resultado. | F8: Pequeno | G8: v2.4-v2.5
B9: A-150-005 | C9: Pedagogia e Currículo | D9: Verdadeiro ou falso matemático | E9: Frases curtas apresentadas como afirmações (9 é maior que 6, 3 e 2 fazem 5) com botões de verdadeiro e falso, treinando o julgamento e o vocabulário matemático. | F9: Pequeno | G9: v2.4-v2.5
B10: A-150-006 | C10: Pedagogia e Currículo | D10: Somar três parcelas | E10: Contas com três grupos visuais (4 + 3 + 2) organizados da esquerda para a direita, preparando a soma de múltiplos termos com apoio de objetos contáveis. | F10: Médio | G10: v2.6-v2.9
B11: A-150-007 | C11: Pedagogia e Currículo | D11: Famílias de fatos | E11: Quatro cartas conectadas (4+3, 3+4, 7−3, 7−4) mostrando que soma e subtração são o mesmo segredo contado de jeitos diferentes, com virada animada entre as cartas. | F11: Médio | G11: v2.6-v2.9
B12: A-150-008 | C12: Pedagogia e Currículo | D12: Arredondamento na feira | E12: Aproximar valores para a dezena mais próxima (23 fica perto de 20) com caixas de frutas ilustradas, base do cálculo mental estimado do dia a dia. | F12: Médio | G12: v2.6-v2.9
B13: A-150-009 | C13: Pedagogia e Currículo | D13: Ordinais na corrida | E13: Perguntas de posição (quem chegou em 3º lugar?) com corridinhas ilustradas, apresentando primeiro, segundo e terceiro nas três línguas do jogo. | F13: Pequeno | G13: v2.6-v2.9
B14: A-150-010 | C14: Pedagogia e Currículo | D14: Calendário da criança | E14: Mini-calendário explorável com dias da semana, semanas e meses em que a criança marca o dia de hoje e conta quantos faltam para eventos (aniversário, fim de semana). | F14: Médio | G14: v2.6-v2.9
B15: A-150-011 | C15: Pedagogia e Currículo | D15: Termômetro e temperatura | E15: Comparar marcas de termômetro (mais quente, mais frio) e somar ou subtrair graus simples, apresentando números abaixo de zero de forma visual em cidades geladas. | F15: Médio | G15: v3.x
... B54: A-150-050 | C54: Pedagogia e Currículo | D54: Linha do número explorável | E54: Reta numérica de 0 a 20 (depois até 100) como brinquedo: pular de 2 em 2, esconder um número para adivinhar, medir pulos, tornando a base do cálculo mental um lugar para brincar. | F54: Médio | G54: v2.4-v2.5

Sheet Médio impacto (50)
B2: Melhorias de médio impacto — 50 itens inéditos
B4: ID | C4: Domínio | D4: Melhoria | E4: Descrição | F4: Esforço | G4: Faixa sugerida
B5: M-150-001 | C5: Modos de Jogo e Conteúdo | D5: Respostas por arrastar | E5: Alternativa de interação em que as respostas são arrastadas até o balão da raposa (com retorno elástico se errar o alvo), variando a mecânica e ajudando quem ainda coordena mal o clique. | F5: Médio | G5: v2.6-v2.9
B6: M-150-002 | C6: Modos de Jogo e Conteúdo | D6: Rodada sob medida | E6: Antes de começar, marca-se 2 ou 3 habilidades para a rodada misturar (somar + dinheiro + sequências), criando treinos direcionados de forma simples e rápida. | F6: Pequeno | G6: v2.4-v2.5
B7: M-150-003 | C7: Modos de Jogo e Conteúdo | D7: Botão pular educativo | E7: Duas vezes por rodada a criança pode pular a questão: ela vai para o fim da fila e volta com dica maior, ensinando que sair e voltar é estratégia, não derrota. | F7: Pequeno | G7: v2.4-v2.5
B8: M-150-004 | C8: Modos de Jogo e Conteúdo | D8: Cruzadinha dos números | E8: Pequenas cruzadinhas em que as respostas são números por extenso ou resultados de contas, com pistas faladas pela raposa, unindo matemática e alfabetização. | F8: Médio | G8: v2.6-v2.9
B9: M-150-005 | C9: Modos de Jogo e Conteúdo | D9: Sopa de números | E9: Grade de letras com números por extenso escondidos (DOIS, SETE) e versão com resultados de contas como pistas, jogável com o dedo arrastando a seleção. | F9: Médio | G9: v2.6-v2.9
B10: M-150-006 | C10: Modos de Jogo e Conteúdo | D10: Ligue os pontos | E10: Desenhos ocultos revelados ao conectar pontos numerados em ordem (depois em pulos de 2 e 5), com a raposa colorindo o desenho ao completar, do passatempo clássico ao salto numérico. | F10: Pequeno | G10: v2.4-v2.5
B11: M-150-007 | C11: Modos de Jogo e Conteúdo | D11: Labirinto dos resultados | E11: Labirintos em que só abrem passagem os caminhos cujas portas mostram o resultado certo da conta, combinando raciocínio espacial e cálculo em níveis curtos. | F11: Médio | G11: v2.6-v2.9
B12: M-150-008 | C12: Modos de Jogo e Conteúdo | D12: Escolha múltipla (marque todas) | E12: Formato de questão com várias respostas certas (quais contas dão 8?) em que a criança marca todas, treinando a varredura completa em vez de parar na primeira. | F12: Pequeno | G12: v2.6-v2.9
B13: M-150-009 | C13: Modos de Jogo e Conteúdo | D13: A raposa erra de propósito | E13: Modo em que a raposa resolve em voz alta e às vezes erra; a criança precisa perceber e corrigir (Não! 5 e 3 é 8!), papel invertido que aprofunda a segurança no cálculo. | F13: Médio | G13: v2.6-v2.9
B14: M-150-010 | C14: Modos de Jogo e Conteúdo | D14: Histórias do folclore | E14: Pacote de histórias narradas com personagens do folclore brasileiro (Saci, Curupira, Boitatá) em que as continhas fazem parte do enredo, com cenas ilustradas. | F14: Médio | G14: v2.6-v2.9
B15: M-150-011 | C15: Modos de Jogo e Conteúdo | D15: Amarelinha matemática | E15: Amarelinha desenhada na tela: pular até a casa com o resultado certo, com cadência de pulos sonora, trazendo o brinquedo de rua para dentro do aplicativo. | F15: Médio | G15: v2.6-v2.9
... B54: M-150-050 | C54: Internacionalização | D54: Modo bilíngue na tela | E54: Rótulos essenciais mostrados em dois idiomas ao mesmo tempo (o segundo em letra menor abaixo do principal) para escolas bilíngues e famílias alfabetizando em duas línguas. | F54: Médio | G54: v2.6-v2.9

Sheet Baixo impacto (50)
B2: Melhorias de baixo impacto — 50 itens inéditos
B4: ID | C4: Domínio | D4: Melhoria | E4: Descrição | F4: Esforço | G4: Faixa sugerida
B5: B-150-001 | C5: Interface e Navegação | D5: Numpad físico mapeado | E5: Garantir que as teclas do teclado numérico do notebook (0-9 e Enter) respondam igualmente às teclas da linha de cima nas respostas digitáveis. | F5: Pequeno | G5: v2.4-v2.5
B6: B-150-002 | C6: Interface e Navegação | D6: Telas ultra-wide | E6: Ajuste de largura máxima do contêiner principal para monitores ultralargos, evitando cartões esticados demais e mantendo o jogo centralizado e confortável. | F6: Pequeno | G6: v2.4-v2.5
B7: B-150-003 | C7: Interface e Navegação | D7: Margem segura para notch | E7: Respeitar safe-area-inset em telas recortadas e no modo tela cheia de tablets, para que nada fique escondido atrás de câmeras ou bordas do aparelho. | F7: Pequeno | G7: v2.4-v2.5
B8: B-150-004 | C8: Interface e Navegação | D8: Título da aba dinâmico | E8: O título da janela mostra o momento (12 estrelas · Conta Comigo, ou Pausado · Conta Comigo), ajudando a achar a janela certa entre muitas abas abertas. | F8: Pequeno | G8: v2.4-v2.5
B9: B-150-005 | C9: Interface e Navegação | D9: Layout compacto 1366px | E9: Preset de espaçamentos para notebooks comuns de 1366x768, garantindo que a tela inicial e o jogo caibam sem rolagem em uma das telas mais usadas nas escolas. | F9: Pequeno | G9: v2.4-v2.5
B10: B-150-006 | C10: Interface e Navegação | D10: Overlay de atalhos (tecla ?) | E10: Pressionar ? abre um cartão com todos os atalhos de teclado organizados por grupo, acessível também por um botão discreto nas opções. | F10: Pequeno | G10: v2.4-v2.5
B11: B-150-007 | C11: Interface e Navegação | D11: ESC fecha overlays | E11: Tecla ESC fecha qualquer sobreposição aberta (fim de rodada, dica, loja), comportamento padrão esperado por quem navega com o teclado. | F11: Pequeno | G11: v2.4-v2.5
B12: B-150-008 | C12: Interface e Navegação | D12: Busca de modos na home | E12: Campo discreto de busca que filtra os cartões de modo enquanto se digita (escrever dino já aponta para os modos de bicho), útil à medida que a lista crescer. | F12: Pequeno | G12: v2.6-v2.9
B13: B-150-009 | C13: Interface e Navegação | D13: Trocar perfil por teclado | E13: Ctrl+1 a Ctrl+4 alternam diretamente entre os perfis com aviso rápido de confirmação, para famílias que dividem o mesmo aparelho em sequência. | F13: Pequeno | G13: v2.6-v2.9
B14: B-150-010 | C14: Interface e Navegação | D14: Grade 3 colunas em telas médias | E14: Nos monitores entre 700 e 1000 pixels, a grade de modos usa 3 colunas equilibradas em vez de 2 ou 6, evitando cartões gigantes ou espremidos. | F14: Pequeno | G14: v2.4-v2.5
B15: B-150-011 | C15: Interface e Navegação | D15: Scroll suave no painel | E15: Rolagem com transição calma nas opções e no painel, evitando saltos bruscos ao alternar seções e mantendo a posição atual ao fechar cartões. | F15: Pequeno | G15: v2.6-v2.9
... B54: B-150-050 | C54: Qualidade e Ferramentas | D54: Parâmetros de depuração na URL | E54: Modo de teste por endereço (nivel=3, modo=somar, sem tempo) para acessar estados específicos sem navegar manualmente, acelerando o QA e as demonstrações. | F54: Pequeno | G54: v2.4-v2.5
